<?xml version='1.0' encoding='utf-8'?>
<robot name="ur5_rg2">
  <link name="base_link">
    <visual name="base_link_visual">
      <geometry>
        <mesh filename="meshes/visual/ur5/base.dae" />
      </geometry>
    </visual>
    <collision name="base_link_collision">
      <geometry>
        <mesh filename="meshes/collision/ur5/base.stl" />
      </geometry>
    </collision>
  </link>

  <link name="shoulder_link">
    <visual name="shoulder_link_visual">
      <geometry>
        <mesh filename="meshes/visual/ur5/shoulder.dae" />
      </geometry>
    </visual>
    <collision name="shoulder_link_collision">
      <geometry>
        <mesh filename="meshes/collision/ur5/shoulder.stl" />
      </geometry>
    </collision>
  </link>

  <link name="upper_arm_link">
    <visual name="upper_arm_link_visual">
      <geometry>
        <mesh filename="meshes/visual/ur5/upperarm.dae" />
      </geometry>
    </visual>
    <collision name="upper_arm_link_collision">
      <geometry>
        <mesh filename="meshes/collision/ur5/upperarm.stl" />
      </geometry>
    </collision>
  </link>

  <link name="forearm_link">
    <visual name="forearm_link_visual">
      <geometry>
        <mesh filename="meshes/visual/ur5/forearm.dae" />
      </geometry>
    </visual>
    <collision name="forearm_link_collision">
      <geometry>
        <mesh filename="meshes/collision/ur5/forearm.stl" />
      </geometry>
    </collision>
  </link>

  <link name="wrist_1_link">
    <visual name="wrist_1_link_visual">
      <geometry>
        <mesh filename="meshes/visual/ur5/wrist1.dae" />
      </geometry>
    </visual>
    <collision name="wrist_1_link_collision">
      <geometry>
        <mesh filename="meshes/collision/ur5/wrist1.stl" />
      </geometry>
    </collision>
  </link>

  <link name="wrist_2_link">
    <visual name="wrist_2_link_visual">
      <geometry>
        <mesh filename="meshes/visual/ur5/wrist2.dae" />
      </geometry>
    </visual>
    <collision name="wrist_2_link_collision">
      <geometry>
        <mesh filename="meshes/collision/ur5/wrist2.stl" />
      </geometry>
    </collision>
  </link>

  <link name="wrist_3_link">
    <visual name="wrist_3_link_visual">
      <geometry>
        <mesh filename="meshes/visual/ur5/wrist3.dae" />
      </geometry>
    </visual>
    <collision name="wrist_3_link_collision">
      <geometry>
        <mesh filename="meshes/collision/ur5/wrist3.stl" />
      </geometry>
    </collision>
  </link>

  <joint name="shoulder_pan_joint" type="revolute">
    <parent link="base_link" />
    <child link="shoulder_link" />
    <origin xyz="0 0 0.089159" rpy="0 0 0" />
    <axis xyz="0 0 1" />
    <limit lower="-6.28319" upper="6.28319" effort="150.0" velocity="3.15" />
  </joint>

  <joint name="shoulder_lift_joint" type="revolute">
    <parent link="shoulder_link" />
    <child link="upper_arm_link" />
    <origin xyz="0 0.13585 0" rpy="0 0 0" />
    <axis xyz="0 1 0" />
    <limit lower="-6.28319" upper="6.28319" effort="150.0" velocity="3.15" />
  </joint>

  <joint name="elbow_joint" type="revolute">
    <parent link="upper_arm_link" />
    <child link="forearm_link" />
    <origin xyz="0 -0.1197 0.425" rpy="0 0 0" />
    <axis xyz="0 1 0" />
    <limit lower="-6.28319" upper="6.28319" effort="150.0" velocity="3.15" />
  </joint>

  <joint name="wrist_1_joint" type="revolute">
    <parent link="forearm_link" />
    <child link="wrist_1_link" />
    <origin xyz="0 0 0.39225" rpy="0 0 0" />
    <axis xyz="0 1 0" />
    <limit lower="-6.28319" upper="6.28319" effort="28.0" velocity="3.2" />
  </joint>

  <joint name="wrist_2_joint" type="revolute">
    <parent link="wrist_1_link" />
    <child link="wrist_2_link" />
    <origin xyz="0 0.093 0" rpy="0 0 0" />
    <axis xyz="0 0 1" />
    <limit lower="-6.28319" upper="6.28319" effort="28.0" velocity="3.2" />
  </joint>

  <joint name="wrist_3_joint" type="revolute">
    <parent link="wrist_2_link" />
    <child link="wrist_3_link" />
    <origin xyz="0 0 0.09465" rpy="0 0 0" />
    <axis xyz="0 1 0" />
    <limit lower="-6.28319" upper="6.28319" effort="28.0" velocity="3.2" />
  </joint>

  <joint name="ur5_hand_joint" type="fixed">
    <parent link="wrist_3_link" />
    <child link="hand_link" />
    <origin xyz="0 0.0823 0" rpy="1.570796325 0 1.570796325" />
    <limit lower="0" upper="0" effort="0" velocity="0" />
  </joint>

  <link name="hand_link">
    <collision>
      <origin xyz="0 0 0" rpy="0 0 0" />
      <geometry>
        <mesh filename="meshes/collision/rg2_description/RG2_Hand_col.STL" />
      </geometry>
    </collision>
    <visual>
      <origin xyz="0 0 0" rpy="0 0 0" />
      <geometry>
        <mesh filename="meshes/visual/rg2_description/RG2_Hand_vis.STL" />
      </geometry>
    </visual>
    <inertial>
      <origin xyz="0.061902 0.000129 -0.000005" rpy="0 0 0" />
      <mass value="1.684558" />
      <inertia ixx="0.000862" ixy="0.0" ixz="0.0" iyy="0.002401" iyz="-0.000001" izz="0.002620" />
    </inertial>
  </link>

  <joint name="gripper_joint" type="revolute">
    <parent link="hand_link" />
    <child link="l_moment_arm_link" />
    <origin xyz="0.105 0.017 0.010" rpy="0 0 0" />
    <axis xyz="0 0 1" />
    <limit velocity="3.14" effort="10.6" lower="-0.45" upper="1.570796327" />
    <dynamics damping="0.1" friction="0.0" />
  </joint>

  <link name="l_moment_arm_link">
    <collision>
      <origin xyz="0 0 0" rpy="0 0 0" />
      <geometry>
        <mesh filename="meshes/collision/rg2_description/RG2_LeftMomentArm_col.STL" />
      </geometry>
    </collision>
    <visual>
      <origin xyz="0 0 0" rpy="0 0 0" />
      <geometry>
        <mesh filename="meshes/visual/rg2_description/RG2_LeftMomentArm_vis.STL" />
      </geometry>
    </visual>
    <inertial>
      <origin xyz="0.017004 0.006397 -0.010300" rpy="0 0 0" />
      <mass value="0.160209" />
      <inertia ixx="0.000023" ixy="0.000019" ixz="0.0" iyy="0.000072" iyz="0.0" izz="0.000083" />
    </inertial>
  </link>

  <joint name="l_finger_2_joint" type="revolute">
    <parent link="l_moment_arm_link" />
    <child link="l_finger_link" />
    <origin xyz="0.049 0.026 0.000" rpy="0 0 0" />
    <axis xyz="0 0 1" />
    <limit velocity="3.14" effort="10.6" lower="-1.570796327" upper="1.570796327" />
    <mimic joint="gripper_joint" multiplier="-1" />
    <dynamics damping="0.1" friction="0.0" />
  </joint>

  <link name="l_finger_link">
    <collision>
      <origin xyz="0 0 0" rpy="0 0 0" />
      <geometry>
        <mesh filename="meshes/collision/rg2_description/RG2_LeftFinger_col.STL" />
      </geometry>
    </collision>
    <visual>
      <origin xyz="0 0 0" rpy="0 0 0" />
      <geometry>
        <mesh filename="meshes/visual/rg2_description/RG2_LeftFinger_vis.STL" />
      </geometry>
    </visual>
    <inertial>
      <origin xyz="0.024695 -0.010178 -0.010001" rpy="0 0 0" />
      <mass value="0.081638" />
      <inertia ixx="0.000006" ixy="-0.000005" ixz="0.0" iyy="0.000025" iyz="0.0" izz="0.000026" />
    </inertial>
  </link>

  <joint name="l_finger_passive_joint" type="revolute">
    <parent link="hand_link" />
    <child link="l_truss_arm_link" />
    <origin xyz="0.122 0.008 0.010" rpy="0 0 0" />
    <axis xyz="0 0 1" />
    <limit velocity="3.14" effort="10.6" lower="-1.570796327" upper="1.570796327" />
    <mimic joint="gripper_joint" multiplier="1" />
    <dynamics damping="0.1" friction="0.0" />
  </joint>

  <link name="l_truss_arm_link">
    <collision>
      <origin xyz="0 0 0" rpy="0 0 0" />
      <geometry>
        <mesh filename="meshes/collision/rg2_description/RG2_LeftTrussArm_col.STL" />
      </geometry>
    </collision>
    <visual>
      <origin xyz="0 0 0" rpy="0 0 0" />
      <geometry>
        <mesh filename="meshes/visual/rg2_description/RG2_LeftTrussArm_vis.STL" />
      </geometry>
    </visual>
    <inertial>
      <origin xyz="0.023075 0.012136 -0.010000" rpy="0 0 0" />
      <mass value="0.065927" />
      <inertia ixx="0.000010" ixy="0.000010" ixz="0.0" iyy="0.000024" iyz="0.0" izz="0.000025" />
    </inertial>
  </link>

  <joint name="r_finger_1_joint" type="revolute">
    <parent link="hand_link" />
    <child link="r_moment_arm_link" />
    <origin xyz="0.105 -0.017 0.010" rpy="0 0 0" />
    <axis xyz="0 0 1" />
    <limit velocity="3.14" effort="10.6" lower="-1.570796327" upper="1.570796327" />
    <mimic joint="gripper_joint" multiplier="-1" />
    <dynamics damping="0.1" friction="0.0" />
  </joint>

  <link name="r_moment_arm_link">
    <collision>
      <origin xyz="0 0 0" rpy="0 0 0" />
      <geometry>
        <mesh filename="meshes/collision/rg2_description/RG2_RightMomentArm_col.STL" />
      </geometry>
    </collision>
    <visual>
      <origin xyz="0 0 0" rpy="0 0 0" />
      <geometry>
        <mesh filename="meshes/visual/rg2_description/RG2_RightMomentArm_vis.STL" />
      </geometry>
    </visual>
    <inertial>
      <origin xyz="0.017004 -0.006397 -0.010300" rpy="0 0 0" />
      <mass value="0.160209" />
      <inertia ixx="0.000023" ixy="-0.000019" ixz="0.0" iyy="0.000072" iyz="0.0" izz="0.000083" />
    </inertial>
  </link>

  <joint name="r_finger_2_joint" type="revolute">
    <parent link="r_moment_arm_link" />
    <child link="r_finger_link" />
    <origin xyz="0.049 -0.026 0.000" rpy="0 0 0" />
    <axis xyz="0 0 1" />
    <limit velocity="3.14" effort="10.6" lower="-1.570796327" upper="1.570796327" />
    <mimic joint="gripper_joint" multiplier="1" />
    <dynamics damping="0.1" friction="0.0" />
  </joint>

  <link name="r_finger_link">
    <collision>
      <origin xyz="0 0 0" rpy="0 0 0" />
      <geometry>
        <mesh filename="meshes/collision/rg2_description/RG2_RightFinger_col.STL" />
      </geometry>
    </collision>
    <visual>
      <origin xyz="0 0 0" rpy="0 0 0" />
      <geometry>
        <mesh filename="meshes/visual/rg2_description/RG2_RightFinger_vis.STL" />
      </geometry>
    </visual>
    <inertial>
      <origin xyz="0.024695 0.010178 -0.010000" rpy="0 0 0" />
      <mass value="0.081637" />
      <inertia ixx="0.000006" ixy="0.000005" ixz="0.0" iyy="0.000025" iyz="0.0" izz="0.000026" />
    </inertial>
  </link>

  <joint name="r_finger_passive_joint" type="revolute">
    <parent link="hand_link" />
    <child link="r_truss_arm_link" />
    <origin xyz="0.122 -0.008 0.010" rpy="0 0 0" />
    <axis xyz="0 0 1" />
    <limit velocity="3.14" effort="10.6" lower="-1.570796327" upper="1.570796327" />
    <mimic joint="gripper_joint" multiplier="-1" />
    <dynamics damping="0.1" friction="0.0" />
  </joint>

  <link name="r_truss_arm_link">
    <collision>
      <origin xyz="0 0 0" rpy="0 0 0" />
      <geometry>
        <mesh filename="meshes/collision/rg2_description/RG2_RightTrussArm_col.STL" />
      </geometry>
    </collision>
    <visual>
      <origin xyz="0 0 0" rpy="0 0 0" />
      <geometry>
        <mesh filename="meshes/visual/rg2_description/RG2_RightTrussArm_vis.STL" />
      </geometry>
    </visual>
    <inertial>
      <origin xyz="0.023075 -0.012136 -0.010000" rpy="0 0 0" />
      <mass value="0.065927" />
      <inertia ixx="0.000010" ixy="-0.000010" ixz="0.0" iyy="0.000024" iyz="0.0" izz="0.000025" />
    </inertial>
  </link>

  <link name="tool0" />
  <joint name="end_effector_frame_fixed_joint" type="fixed">
    <parent link="wrist_3_link" />
    <child link="tool0" />
    <origin xyz="0 0.275 0" rpy="-1.570796325 0 0" />
  </joint>
</robot>
